Workbook

Sheet Sheet1
A1: loan_key | B1: nid | C1: No. of Loans | D1: customer_name | E1: customer_key | F1: Bucket Was | G1: Bucket Is | H1: Type | I1: Owner | J1: Outstanding Principal | K1: Receivables Outstanding | L1: OVD | M1: PMT | N1: Agency Payment | O1: Date of Payment | P1: collector | Q1: code | R1: s.v | S1: code | T1: head | U1: code
A2: 1000263501 | B2: 29911112301196 | C2: 2 | D2: عبد الرحمن عيد علي عبد القوي | E2: 10002635 | F2: Charged-off | G2: Charged-off | H2: W.O | I2: Qima | J2: 7056030 | K2: 14808521 | L2: 2467381 | M2: 251860 | N2: 0 | P2: قيمه | R2: رحاب عبد الهادى احمد بدوى | S2: 54 | T2: محمود النادى أبو الحسن احمد | U2: 31
A3: 1000248701 | B3: 28706073200232 | C3: 2 | D3: مصطفي امين زيدان عبد العال | E3: 10002487 | F3: Bucket 5 | G3: Bucket 5 | H3: Active | I3: Qima | J3: 3967150 | K3: 7929169 | L3: 832744 | M3: 144825 | N3: 0 | P3: قيمه | R3: رحاب عبد الهادى احمد بدوى | S3: 54 | T3: محمود النادى أبو الحسن احمد | U3: 31
A4: 1000942701 | B4: 28003040100142 | C4: 2 | D4: كريستين سعيد جيد جرجس | E4: 10009427 | F4: Bucket 4 | G4: Bucket 4 | H4: Active | I4: Qima | J4: 1062270 | K4: 2136139 | L4: 173204 | M4: 38490 | N4: 0 | P4: قيمه | R4: رحاب عبد الهادى احمد بدوى | S4: 54 | T4: محمود النادى أبو الحسن احمد | U4: 31
A5: 1000263502 | B5: 29911112301196 | C5: 2 | D5: عبد الرحمن عيد علي عبد القوي | E5: 10002635 | F5: Charged-off | G5: Charged-off | H5: W.O | I5: Qima | J5: 195160 | K5: 286905 | L5: 262000 | M5: 24905 | N5: 0 | P5: قيمه | R5: رحاب عبد الهادى احمد بدوى | S5: 54 | T5: محمود النادى أبو الحسن احمد | U5: 31
A6: 1000346001 | B6: 29109150107114 | C6: 1 | D6: محمد عيد صالح محمود | E6: 10003460 | F6: Bucket 2 | G6: Bucket 2 | H6: Active | I6: Qima | J6: 166455 | K6: 273285 | L6: 20695 | M6: 9715 | N6: 0 | P6: ياسمين محمد رشاد الشحات | Q6: 732 | R6: رحاب عبد الهادى احمد بدوى | S6: 54 | T6: محمود النادى أبو الحسن احمد | U6: 31
A7: 1000029802 | B7: 27906262601634 | C7: 2 | D7: رجب خطاب فاضل محمد | E7: 10000298 | F7: Bucket 3 | G7: Current | H7: Active | I7: Qima | J7: 162230 | K7: 264590 | L7: 37055 | M7: 10835 | N7: 37055 | O7: 45955 | P7: ياسمين محمد رشاد الشحات | Q7: 732 | R7: رحاب عبد الهادى احمد بدوى | S7: 54 | T7: محمود النادى أبو الحسن احمد | U7: 31
A8: 1000248702 | B8: 28706073200232 | C8: 2 | D8: مصطفي امين زيدان عبد العال | E8: 10002487 | F8: Bucket 6 | G8: Bucket 6 | H8: Active | I8: Qima | J8: 155950 | K8: 201791 | L8: 176886 | M8: 24905 | N8: 0 | P8: قيمه | R8: رحاب عبد الهادى احمد بدوى | S8: 54 | T8: محمود النادى أبو الحسن احمد | U8: 31
A9: 1000025501 | B9: 29603121401822 | C9: 1 | D9: مريم محمد مصطفى محمود حمزة | E9: 10000255 | F9: Bucket 2 | G9: Bucket 2 | H9: Active | I9: Qima | J9: 155595 | K9: 237238 | L9: 22513 | M9: 10225 | N9: 0 | P9: مريم جابر إسماعيل | Q9: 772 | R9: رحاب عبد الهادى احمد بدوى | S9: 54 | T9: محمود النادى أبو الحسن احمد | U9: 31
A10: 1000456901 | B10: 29208011708403 | C10: 1 | D10: دينا حسام الدين محمد فرج حما | E10: 10004569 | F10: Bucket 5 | G10: Bucket 2 | H10: Active | I10: Qima | J10: 133380 | K10: 275489 | L10: 26864 | M10: 4875 | N10: 16110 | O10: 45949 | P10: ياسمين محمد رشاد الشحات | Q10: 732 | R10: رحاب عبد الهادى احمد بدوى | S10: 54 | T10: محمود النادى أبو الحسن احمد | U10: 31
A11: 1000839401 | B11: 29401201600352 | C11: 1 | D11: حماده سليمان رمضان ابراهيم الدش | E11: 10008394 | F11: Bucket 4 | G11: Bucket 4 | H11: Active | I11: Qima | J11: 132550 | K11: 248330 | L11: 23440 | M11: 5230 | N11: 0 | P11: ياسمين محمد رشاد الشحات | Q11: 732 | R11: رحاب عبد الهادى احمد بدوى | S11: 54 | T11: محمود النادى أبو الحسن احمد | U11: 31
A12: 1001016701 | B12: 28712031500171 | C12: 1 | D12: احمد فتوح عبدالعزيز احمد ابراهيم | E12: 10010167 | F12: Bucket 2 | G12: Bucket 2 | H12: Active | I12: Qima | J12: 120500 | K12: 197381 | L12: 12047 | M12: 5451 | N12: 0 | P12: ياسمين محمد رشاد الشحات | Q12: 732 | R12: رحاب عبد الهادى احمد بدوى | S12: 54 | T12: محمود النادى أبو الحسن احمد | U12: 31
A13: 1000033401 | B13: 27004210200573 | C13: 2 | D13: خالد على سعيد الديب | E13: 10000334 | F13: Bucket 2 | G13: Bucket 2 | H13: Active | I13: Qima | J13: 118620 | K13: 188697 | L13: 17967 | M13: 8130 | N13: 0 | P13: ياسمين محمد رشاد الشحات | Q13: 732 | R13: رحاب عبد الهادى احمد بدوى | S13: 54 | T13: محمود النادى أبو الحسن احمد | U13: 31
A14: 1000811001 | B14: 28609171600332 | C14: 1 | D14: احمد شعبان منير على يونس | E14: 10008110 | F14: Bucket 6 | G14: Bucket 6 | H14: Active | I14: Qima | J14: 106170 | K14: 191668 | L14: 48558 | M14: 6505 | N14: 0 | P14: ياسمين محمد رشاد الشحات | Q14: 732 | R14: رحاب عبد الهادى احمد بدوى | S14: 54 | T14: محمود النادى أبو الحسن احمد | U14: 31
A15: 1000942702 | B15: 28003040100142 | C15: 2 | D15: كريستين سعيد جيد جرجس | E15: 10009427 | F15: Bucket 4 | G15: Bucket 4 | H15: Active | I15: Qima | J15: 96570 | K15: 195452 | L15: 16497 | M15: 3510 | N15: 0 | P15: قيمه | R15: رحاب عبد الهادى احمد بدوى | S15: 54 | T15: محمود النادى أبو الحسن احمد | U15: 31
A16: 1000431501 | B16: 29006260300072 | C16: 3 | D16: وليد كمال صبحي احمد عبدالله | E16: 10004315 | F16: Bucket 4 | G16: Bucket 4 | H16: Active | I16: Qima | J16: 95484 | K16: 176094 | L16: 26109 | M16: 5555 | N16: 0 | P16: مريم جابر إسماعيل | Q16: 772 | R16: رحاب عبد الهادى احمد بدوى | S16: 54 | T16: محمود النادى أبو الحسن احمد | U16: 31
A17: 1000418801 | B17: 27106032101776 | C17: 1 | D17: محمود احمد محمد سرحان | E17: 10004188 | F17: Bucket 4 | G17: Bucket 2 | H17: Active | I17: Qima | J17: 89305 | K17: 121394 | L17: 44434 | M17: 9620 | N17: 24200 | O17: 45961 | P17: مريم جابر إسماعيل | Q17: 772 | R17: رحاب عبد الهادى احمد بدوى | S17: 54 | T17: محمود النادى أبو الحسن احمد | U17: 31
A18: 1000139901 | B18: 28211270105501 | C18: 1 | D18: مهجه جاد محمد عبداللطيف | E18: 10001399 | F18: Bucket 6 | G18: Bucket 6 | H18: Active | I18: Qima | J18: 83310 | K18: 130051 | L18: 49831 | M18: 6685 | N18: 0 | P18: كريمه هانى | R18: رحاب عبد الهادى احمد بدوى | S18: 54 | T18: محمود النادى أبو الحسن احمد | U18: 31
A19: 1000558501 | B19: 28610151802069 | C19: 2 | D19: هبه محمود فتح الله عبد اللطيف | E19: 10005585 | F19: Bucket 6 | G19: Bucket 6 | H19: Active | I19: Qima | J19: 82385 | K19: 153832 | L19: 31112 | M19: 4720 | N19: 0 | P19: ياسمين محمد رشاد الشحات | Q19: 732 | R19: رحاب عبد الهادى احمد بدوى | S19: 54 | T19: محمود النادى أبو الحسن احمد | U19: 31
A20: 1000863001 | B20: 27508311500037 | C20: 1 | D20: وليد محمد محمد نوار | E20: 10008630 | F20: Bucket 2 | G20: Current | H20: Active | I20: Qima | J20: 81100 | K20: 131334 | L20: 11984 | M20: 5425 | N20: 11984 | O20: 45959 | P20: مريم جابر إسماعيل | Q20: 772 | R20: رحاب عبد الهادى احمد بدوى | S20: 54 | T20: محمود النادى أبو الحسن احمد | U20: 31
A21: 1000278301 | B21: 28101300100399 | C21: 1 | D21: احمد اسماعيل توفيق حسين | E21: 10002783 | F21: Bucket 4 | G21: Bucket 2 | H21: Active | I21: Qima | J21: 79357 | K21: 112350 | L21: 25445 | M21: 6685 | N21: 11200 | O21: 45960 | P21: ياسمين محمد رشاد الشحات | Q21: 732 | R21: رحاب عبد الهادى احمد بدوى | S21: 54 | T21: محمود النادى أبو الحسن احمد | U21: 31
A22: 1000002201 | B22: 28205200105211 | C22: 1 | D22: عادل ماهر فهيم حنا | E22: 10000022 | F22: Bucket 2 | G22: Bucket 2 | H22: Active | I22: Qima | J22: 79065 | K22: 125905 | L22: 11980 | M22: 5425 | N22: 6000 | O22: 45956 | P22: ياسمين محمد رشاد الشحات | Q22: 732 | R22: رحاب عبد الهادى احمد بدوى | S22: 54 | T22: محمود النادى أبو الحسن احمد | U22: 31
A23: 1000775001 | B23: 29610231701135 | C23: 1 | D23: عبدالله علاء الدين ممد عبد المنصف خلف | E23: 10007750 | F23: Bucket 2 | G23: Bucket 2 | H23: Active | I23: Qima | J23: 77265 | K23: 116248 | L23: 5848 | M23: 2760 | N23: 0 | P23: مريم جابر إسماعيل | Q23: 772 | R23: رحاب عبد الهادى احمد بدوى | S23: 54 | T23: محمود النادى أبو الحسن احمد | U23: 31
A24: 1000144401 | B24: 26604031400351 | C24: 2 | D24: حسني عبدالرؤوف حسين علي | E24: 10001444 | F24: Charged-off | G24: Charged-off | H24: W.O | I24: Qima | J24: 74139 | K24: 115334 | L24: 49939 | M24: 5945 | N24: 0 | P24: كريمه هانى | R24: رحاب عبد الهادى احمد بدوى | S24: 54 | T24: محمود النادى أبو الحسن احمد | U24: 31
A25: 1000845402 | B25: 27106201402063 | C25: 2 | D25: أمانى ابراهيم ابو الخير عبدالله | E25: 10008454 | F25: Bucket 4 | G25: Bucket 3 | H25: Active | I25: Qima | J25: 73725 | K25: 121076 | L25: 15521 | M25: 3405 | N25: 5817 | O25: 45953 | P25: مريم جابر إسماعيل | Q25: 772 | R25: رحاب عبد الهادى احمد بدوى | S25: 54 | T25: محمود النادى أبو الحسن احمد | U25: 31
A26: 1000114401 | B26: 29109120101839 | C26: 1 | D26: مصطفي محمد رضوان حسانين | E26: 10001144 | F26: Bucket 4 | G26: Bucket 3 | H26: Active | I26: Qima | J26: 72380 | K26: 140620 | L26: 12740 | M26: 2780 | N26: 3600 | O26: 45937 | P26: مريم جابر إسماعيل | Q26: 772 | R26: رحاب عبد الهادى احمد بدوى | S26: 54 | T26: محمود النادى أبو الحسن احمد | U26: 31
A27: 1000558502 | B27: 28610151802069 | C27: 2 | D27: هبه محمود فتح الله عبد اللطيف | E27: 10005585 | F27: Bucket 6 | G27: Bucket 6 | H27: Active | I27: Qima | J27: 69330 | K27: 91350 | L27: 80565 | M27: 10785 | N27: 0 | P27: ياسمين محمد رشاد الشحات | Q27: 732 | R27: رحاب عبد الهادى احمد بدوى | S27: 54 | T27: محمود النادى أبو الحسن احمد | U27: 31
A28: 1000448901 | B28: 26607062800674 | C28: 1 | D28: محمد يسري شعبان بحر حسن | E28: 10004489 | F28: Bucket 4 | G28: Bucket 3 | H28: Active | I28: Qima | J28: 69159 | K28: 124184 | L28: 14294 | M28: 4070 | N28: 400 | O28: 45961 | P28: سلمي يونس محمد | Q28: 763 | R28: رحاب عبد الهادى احمد بدوى | S28: 54 | T28: محمود النادى أبو الحسن احمد | U28: 31
A29: 1000125101 | B29: 27609080101062 | C29: 1 | D29: سيده فرج الله بلال مرسال | E29: 10001251 | F29: Bucket 5 | G29: Bucket 5 | H29: Active | I29: Qima | J29: 68895 | K29: 138195 | L29: 15760 | M29: 2605 | N29: 0 | P29: كريمه هانى | R29: رحاب عبد الهادى احمد بدوى | S29: 54 | T29: محمود النادى أبو الحسن احمد | U29: 31
A30: 1000408601 | B30: 28107111701576 | C30: 1 | D30: محمد نبيل عبدالعزيز شعبان | E30: 10004086 | F30: Bucket 4 | G30: Bucket 4 | H30: Active | I30: Qima | J30: 63183 | K30: 111894 | L30: 13094 | M30: 3800 | N30: 0 | P30: ياسمين محمد رشاد الشحات | Q30: 732 | R30: رحاب عبد الهادى احمد بدوى | S30: 54 | T30: محمود النادى أبو الحسن احمد | U30: 31
A31: 1000662502 | B31: 27601211301011 | C31: 2 | D31: صبري احمد ابراهيم ابراهيم | E31: 10006625 | F31: Bucket 2 | G31: Bucket 2 | H31: Active | I31: Qima | J31: 60670 | K31: 80027 | L31: 10277 | M31: 4650 | N31: 0 | P31: مريم جابر إسماعيل | Q31: 772 | R31: رحاب عبد الهادى احمد بدوى | S31: 54 | T31: محمود النادى أبو الحسن احمد | U31: 31
A32: 1000662501 | B32: 27601211301011 | C32: 2 | D32: صبري احمد ابراهيم ابراهيم | E32: 10006625 | F32: Bucket 2 | G32: Bucket 2 | H32: Active | I32: Qima | J32: 60670 | K32: 79699 | L32: 9949 | M32: 4650 | N32: 0 | P32: مريم جابر إسماعيل | Q32: 772 | R32: رحاب عبد الهادى احمد بدوى | S32: 54 | T32: محمود النادى أبو الحسن احمد | U32: 31
A33: 1000736101 | B33: 27007211400559 | C33: 1 | D33: ايهاب سعد اسماعيل متولي | E33: 10007361 | F33: Bucket 4 | G33: Bucket 4 | H33: Active | I33: Qima | J33: 60646 | K33: 93487 | L33: 7387 | M33: 2100 | N33: 0 | P33: مريم جابر إسماعيل | Q33: 772 | R33: رحاب عبد الهادى احمد بدوى | S33: 54 | T33: محمود النادى أبو الحسن احمد | U33: 31
A34: 1000728501 | B34: 28111158800073 | C34: 1 | D34: هاني مصطفى محمود على الجيزاوى | E34: 10007285 | F34: Bucket 3 | G34: Bucket 1 | H34: Active | I34: Qima | J34: 60385 | K34: 91152 | L34: 5152 | M34: 2150 | N34: 3000 | O34: 45942 | P34: سلمي يونس محمد | Q34: 763 | R34: رحاب عبد الهادى احمد بدوى | S34: 54 | T34: محمود النادى أبو الحسن احمد | U34: 31
A35: 1000938001 | B35: 28408048800054 | C35: 1 | D35: شريف فتحي نعيم السيد | E35: 10009380 | F35: Charged-off | G35: Charged-off | H35: W.O | I35: Qima | J35: 59905 | K35: 92546 | L35: 45627 | M35: 5215 | N35: 0 | P35: كريمه هانى | R35: رحاب عبد الهادى احمد بدوى | S35: 54 | T35: محمود النادى أبو الحسن احمد | U35: 31
A36: 1000403201 | B36: 27306172800908 | C36: 1 | D36: لمياء هاشم محمود احمد ابوصادق | E36: 10004032 | F36: Bucket 6 | G36: Bucket 6 | H36: Active | I36: Qima | J36: 54040 | K36: 113372 | L36: 14372 | M36: 1980 | N36: 0 | P36: ياسمين محمد رشاد الشحات | Q36: 732 | R36: رحاب عبد الهادى احمد بدوى | S36: 54 | T36: محمود النادى أبو الحسن احمد | U36: 31
A37: 1000000901 | B37: 27206112100406 | C37: 1 | D37: هدي سلامه سعيد ناصر | E37: 10000009 | F37: Bucket 2 | G37: Bucket 2 | H37: Active | I37: Qima | J37: 53635 | K37: 68140 | L37: 14660 | M37: 6685 | N37: 0 | P37: ياسمين محمد رشاد الشحات | Q37: 732 | R37: رحاب عبد الهادى احمد بدوى | S37: 54 | T37: محمود النادى أبو الحسن احمد | U37: 31
A38: 1000222401 | B38: 29502028801038 | C38: 2 | D38: عادل خضر محمد ابو عزيزة | E38: 10002224 | F38: Bucket 4 | G38: Bucket 4 | H38: Active | I38: Qima | J38: 53070 | K38: 93562 | L38: 15322 | M38: 3260 | N38: 0 | P38: ياسمين محمد رشاد الشحات | Q38: 732 | R38: رحاب عبد الهادى احمد بدوى | S38: 54 | T38: محمود النادى أبو الحسن احمد | U38: 31
A39: 1000222402 | B39: 29502028801038 | C39: 2 | D39: عادل خضر محمد ابو عزيزة | E39: 10002224 | F39: Bucket 4 | G39: Bucket 4 | H39: Active | I39: Qima | J39: 53070 | K39: 93499 | L39: 15259 | M39: 3260 | N39: 0 | P39: ياسمين محمد رشاد الشحات | Q39: 732 | R39: رحاب عبد الهادى احمد بدوى | S39: 54 | T39: محمود النادى أبو الحسن احمد | U39: 31
A40: 1000132201 | B40: 29111270200678 | C40: 1 | D40: عمر عصام محمد جلال بيومي فرغلي | E40: 10001322 | F40: Bucket 5 | G40: Bucket 5 | H40: Active | I40: Qima | J40: 53070 | K40: 92478 | L40: 17498 | M40: 3260 | N40: 0 | P40: مريم جابر إسماعيل | Q40: 772 | R40: رحاب عبد الهادى احمد بدوى | S40: 54 | T40: محمود النادى أبو الحسن احمد | U40: 31
...

Sheet Comm
A1: Collected | B1: 0 | C1: 1 | D1: 2 | E1: 3 | F1: 4 | G1: 5 | H1: 6 | I1: Charged-off | J1: Grand Total | L1: Qima | M1: Partial | N1: 1 inst | O1: 2 inst | P1: 3 inst | Q1: 4 inst | R1: 5 inst | S1: 6 inst | T1: Collected amount | U1: Total Comm
A2: Bucket 1 | L2: Bucket 1 | M2: 0 | N2: 0 | U2: =SUM(M2:T2) -> 0 | V2: =SUM(U2:U8) -> 55121.63
A3: Bucket 2 | B3: 6000 | C3: 1966 | D3: 11984 | J3: 19950 | L3: Bucket 2 | M3: 300 | N3: 137.62 | O3: 1078.56 | U3: =SUM(M3:T3) -> 1516.18
A4: Bucket 3 | B4: 0 | C4: 33024 | D4: 15760 | E4: 97250 | J4: 146034 | L4: Bucket 3 | M4: 0 | N4: 2311.68 | O4: 1418.4 | P4: 9725 | U4: =SUM(M4:T4) -> 13455.08
A5: Bucket 4 | B5: 914 | C5: 30172 | D5: 76903 | E5: 6032 | F5: 38289 | J5: 152310 | L5: Bucket 4 | M5: 45.7 | N5: 2112.04 | O5: 6152.24 | P5: 603.2 | Q5: 4211.79 | U5: =SUM(M5:T5) -> 13124.97
A6: Bucket 5 | B6: 9559 | C6: 15346 | D6: 6938 | E6: 33694 | G6: 28222 | J6: 93759 | L6: Bucket 5 | M6: 477.95 | N6: 1074.22 | O6: 555.04 | P6: 3032.46 | Q6: 0 | R6: 3951.08 | U6: =SUM(M6:T6) -> 9090.75
A7: Bucket 6 | B7: 1000 | C7: 15349 | D7: 37200 | E7: 8000 | H7: 50581 | J7: 112130 | L7: Bucket 6 | M7: 50 | N7: 1074.43 | O7: 2976 | P7: 720 | Q7: 0 | R7: 0 | S7: 7081.34 | U7: =SUM(M7:T7) -> 11901.77
A8: Charged-off | I8: 33516 | J8: 33516 | L8: Charged-Off | M8: 0 | N8: 0 | O8: 0 | P8: 0 | Q8: 0 | R8: 0 | S8: 0 | T8: 6032.88 | U8: =SUM(M8:T8) -> 6032.88
A9: Total Collected Amount | J9: =SUM(J3:J8) -> 557699
M11: Partial | N11: 1 inst | O11: 2 inst | P11: 3 inst | Q11: 4 inst | R11: 5 inst | S11: 6 inst | T11: Collected amount
L12: B1 | M12: 0.05 | N12: 0.08
L13: B2 | M13: 0.05 | N13: 0.07 | O13: 0.09
L14: B3 | M14: 0.05 | N14: 0.07 | O14: 0.09 | P14: 0.1
L15: B4 | M15: 0.05 | N15: 0.07 | O15: 0.08 | P15: 0.1 | Q15: 0.11
L16: B5 | M16: 0.05 | N16: 0.07 | O16: 0.08 | P16: 0.09 | Q16: 0.12 | R16: 0.14
L17: B6 | M17: 0.05 | N17: 0.07 | O17: 0.08 | P17: 0.09 | Q17: 0.1 | R17: 0.12 | S17: 0.14
L18: Charged-Off | T18: 0.18

Sheet Piv
B1: وسيلة | C1: 45931
A3: head | B3: s.v | C3: Type | D3: collector | E3: Sum of Agency Payment
A4: محمود النادى أبو الحسن احمد | B4: رحاب عبد الهادى احمد بدوى | C4: Active | D4: سلمي يونس محمد | E4: 72942
D5: كريمه هانى | E5: 81238
D6: مريم جابر إسماعيل | E6: 132695
D7: ياسمين محمد رشاد الشحات | E7: 237308
C8: Active Total | E8: 524183
C9: W.O | D9: سلمي يونس محمد | E9: 7201
D10: كريمه هانى | E10: 1000
D11: مريم جابر إسماعيل | E11: 18500
D12: ياسمين محمد رشاد الشحات | E12: 6815
C13: W.O Total | E13: 33516
B14: رحاب عبد الهادى احمد بدوى Total | E14: 557699
A15: محمود النادى أبو الحسن احمد Total | E15: 557699
A16: Grand Total | E16: 557699
A19: يعتمد | B19: إدارة التحصيل | E19: الإدارة المالية

Sheet العمولة
B1: وسيلة | C1: 45931
A3: head | B3: s.v | C3: Type | D3: collector | E3: Sum of Agency Payment | F3: Rate | G3: العمولة | N3: No
A4: محمود النادى أبو الحسن احمد | B4: رحاب عبد الهادى احمد بدوى | C4: Active | D4: سلمي يونس محمد | E4: 72942 | F4: 0.01 | G4: {=F4:F13*E4:E13} -> 729.42 | L4: Tele | M4: Active | N4: 0.01
D5: كريمه هانى | E5: 81238 | F5: 0.015 | G5: 1218.57 | M5: w/O | N5: 0.015
D6: مريم جابر إسماعيل | E6: 132695 | F6: 0.01 | G6: 1326.95
D7: ياسمين محمد رشاد الشحات | E7: 237308 | F7: 0.01 | G7: 2373.08 | N7: No
C8: Active Total | E8: 524183 | F8: 0.005 | G8: 2620.915 | L8: collector | M8: Active | N8: 0.015
C9: W.O | D9: سلمي يونس محمد | E9: 7201 | F9: 0.015 | G9: 108.015 | M9: w/O | N9: 0.02
D10: كريمه هانى | E10: 1000 | F10: 0.02 | G10: 20
D11: مريم جابر إسماعيل | E11: 18500 | F11: 0.015 | G11: 277.5 | N11: No
D12: ياسمين محمد رشاد الشحات | E12: 6815 | F12: 0.015 | G12: 102.225 | L12: عقود انتاج | M12: collector | N12: 0.02
C13: W.O Total | E13: 33516 | F13: 0.0075 | G13: 251.37 | M13: Tele | N13: 0.015
B14: رحاب عبد الهادى احمد بدوى Total | E14: 557699
A15: محمود النادى أبو الحسن احمد Total | E15: 557699 | N15: No
A16: Grand Total | E16: 557699 | G16: =SUM(G4:G15) -> 9028.045 | L16: S.V | M16: Active | N16: 0.005
M17: w/O | N17: 0.0075
D18: Active | E18: 524183 | F18: 0.0025 | G18: {=+E18:E19*F18:F19} -> 1310.4575
D19: W.O | E19: 33516 | F19: 0.0025 | G19: 83.79
A20: محمود النادى أبو الحسن احمد | G20: =SUM(_xlfn.ANCHORARRAY(G18)) -> 1394.2475
G21: =G20+G16 -> 10422.292
A24: يعتمد | B24: إدارة التحصيل | E24: الإدارة المالية | N24: No
L25: Head | M25: Active | N25: 0.0025
M26: w/O

Sheet ورقة1
A1: الكود | B1: الاسم | C1: عمولات وسيلة
A2: 2 | B2: علاء محمد عوض جاد الله | C2: =SUMIF(العمولة!$D$3:$D$13,ورقة1!B2,العمولة!$G$3:$G$14) -> 0
A3: 4 | B3: وليد عبد الكريم عبد العليم | C3: =SUMIF(العمولة!$D$3:$D$13,ورقة1!B3,العمولة!$G$3:$G$14) -> 0
A4: 5 | B4: باسم صلاح عبد الله قوشتى | C4: =SUMIF(العمولة!$D$3:$D$13,ورقة1!B4,العمولة!$G$3:$G$14) -> 0
A5: 9 | B5: عمرو عصام بدر الدين زكي | C5: =SUMIF(العمولة!$D$3:$D$13,ورقة1!B5,العمولة!$G$3:$G$14) -> 0
A6: 10 | B6: عبد المنعم مجدى عبدربه محمد هلهل | C6: =SUMIF(العمولة!$D$3:$D$13,ورقة1!B6,العمولة!$G$3:$G$14) -> 0
A7: 19 | B7: سحر اوسامة احمد محمد | C7: =SUMIF(العمولة!$D$3:$D$13,ورقة1!B7,العمولة!$G$3:$G$14) -> 0
A8: 20 | B8: عبد العزيز صلاح عبد العزيز على حسن | C8: =SUMIF(العمولة!$D$3:$D$13,ورقة1!B8,العمولة!$G$3:$G$14) -> 0
A9: 31 | B9: محمود النادى أبو الحسن احمد | C9: =العمولة!G20 -> 1394.2475
A10: 35 | B10: رحمة مصطفى خلف الله حسانين | C10: =SUMIF(العمولة!$D$3:$D$13,ورقة1!B10,العمولة!$G$3:$G$14) -> 0
A11: 45 | B11: محمد مجدى ربيع عبد الغنى جاد | C11: =SUMIF(العمولة!$D$3:$D$13,ورقة1!B11,العمولة!$G$3:$G$14) -> 0
A12: 54 | B12: رحاب عبد الهادى احمد بدوى | C12: =العمولة!G13+العمولة!G8 -> 2872.285
A13: 60 | B13: مروة مصطفى على جاد | C13: =SUMIF(العمولة!$D$3:$D$13,ورقة1!B13,العمولة!$G$3:$G$14) -> 0
A14: 62 | B14: محمد مجدى السيد عبد الدايم | C14: =SUMIF(العمولة!$D$3:$D$13,ورقة1!B14,العمولة!$G$3:$G$14) -> 0
A15: 64 | B15: تريز سامى رزق شحاته | C15: =SUMIF(العمولة!$D$3:$D$13,ورقة1!B15,العمولة!$G$3:$G$14) -> 0
A16: 71 | B16: ندى محمد سعد محمد | C16: =SUMIF(العمولة!$D$3:$D$13,ورقة1!B16,العمولة!$G$3:$G$14) -> 0
A17: 83 | B17: حبيبه احمد سلطان منصور عويس | C17: =SUMIF(العمولة!$D$3:$D$13,ورقة1!B17,العمولة!$G$3:$G$14) -> 0
A18: 97 | B18: ندى محمد محمود عبد المقصود | C18: =SUMIF(العمولة!$D$3:$D$13,ورقة1!B18,العمولة!$G$3:$G$14) -> 0
A19: 119 | B19: مصطفى جميل عبد الفتاح محمد شاهين | C19: =SUMIF(العمولة!$D$3:$D$13,ورقة1!B19,العمولة!$G$3:$G$14) -> 0
A20: 125 | B20: زينب محمود محمد محمود صالح | C20: =SUMIF(العمولة!$D$3:$D$13,ورقة1!B20,العمولة!$G$3:$G$14) -> 0
A21: 129 | B21: نانسى يوسف عزيز يوسف | C21: =SUMIF(العمولة!$D$3:$D$13,ورقة1!B21,العمولة!$G$3:$G$14) -> 0
A22: 131 | B22: امانى طارق إبراهيم عبد الحميد | C22: =SUMIF(العمولة!$D$3:$D$13,ورقة1!B22,العمولة!$G$3:$G$14) -> 0
A23: 133 | B23: نادين عماد منصور محمد | C23: =SUMIF(العمولة!$D$3:$D$13,ورقة1!B23,العمولة!$G$3:$G$14) -> 0
A24: 136 | B24: بهاء محمد السيد صالح أبو حسين | C24: =SUMIF(العمولة!$D$3:$D$13,ورقة1!B24,العمولة!$G$3:$G$14) -> 0
... A187: 4444 | B187: Manar Ahmed | C187: =SUMIF(العمولة!$D$3:$D$13,ورقة1!B187,العمولة!$G$3:$G$14) -> 0
A188: الإجمالي | C188: =SUM(C2:C187) -> 10422.292
